<?xml version="1.0" encoding="utf-8"?>
<!-- This URDF was automatically created by SolidWorks to URDF Exporter! Originally created by Stephen Brawner (brawner@gmail.com) 
     Commit Version: 1.6.0-4-g7f85cfe  Build Version: 1.6.7995.38578
     For more information, please see http://wiki.ros.org/sw_urdf_exporter -->
<robot
  name="cyvet">
  <link
    name="BASE_LINK">
    <inertial>
      <origin
        xyz="0.01000403 0.0033084 0.00460078"
        rpy="0 0 0" />
      <mass
        value="7.7" />
      <inertia
        ixx="0.035500153036820775"
        ixy="0.0002995458161983171"
        ixz="-0.005987278547573891"
        iyy="0.09770477451605258"
        iyz="0.0005153480996085439"
        izz="0.114882696016116" />
    </inertial>
    <visual>
      <origin
        xyz="0 0 0"
        rpy="0 0 0" />
      <geometry>
        <mesh
          filename="../meshes/base_link.stl" />
      </geometry>
      <material
        name="">
        <color
          rgba="0.592156862745098 0.666666666666667 0.682352941176471 1" />
      </material>
    </visual>
    <collision>
      <origin
        xyz="-0.005	0.0	0.011469"
        rpy="0.0 0.0 0.0" />
      <geometry>
      <box size="0.49 0.219 0.12"/>
      </geometry>
    </collision>
    <collision>
      <origin
        xyz="0.25239	0.0	-0.00332"
        rpy="0.0 0.22689280275926285 0.0" />
      <geometry>
      <box size="0.025 0.0332 0.09"/>
      </geometry>
    </collision>
    <collision>
      <origin
        xyz="0.23335	0.0	0.076435"
        rpy="0.0 0.0 0.0" />
      <geometry>
      <box size="0.11 0.106 0.072"/>
      </geometry>
    </collision>
  </link>
  <link
    name="FL_ABAD_LINK">
    <inertial>
      <origin
        xyz="0.0224121948144358 -0.0113603891974002 -6.25878030513505e-07"
        rpy="0 0 0" />
      <mass
        value="0.12099999999999998" />
      <inertia
        ixx="8.880926120933786e-05"
        ixy="3.605533318472001e-07"
        ixz="2.079839172613958e-09"
        iyy="0.00011790012071397361"
        iyz="1.4871021896033942e-09"
        izz="0.0001094411485088671" />
    </inertial>
    <visual>
      <origin
        xyz="0 0 0"
        rpy="0 0 0" />
      <geometry>
        <mesh
          filename="../meshes/fl_abad_link.stl" />
      </geometry>
      <material
        name="">
        <color
          rgba="1 1 1 1" />
      </material>
    </visual>
    <collision>
      <origin
        xyz="0.05 0.08 0"
        rpy="0.0000 -1.5708 1.5708" />
      <geometry>
      <cylinder radius="0.04" length="0.055"/>
      </geometry>
    </collision>
  </link>
  <joint
    name="FL_ABAD_JOINT"
    type="revolute">
    <origin
      xyz="0.144 0.064225 -2.0143E-05"
      rpy="0 0 0" />
    <parent
      link="BASE_LINK" />
    <child
      link="FL_ABAD_LINK" />
    <axis
      xyz="1 0 0" />
    <limit
      lower="-0.5233"
      upper="0.5233"
      effort="30"
      velocity="20" />
  </joint>
  <link
    name="FL_HIP_LINK">
    <inertial>
      <origin
        xyz="-0.00194205 0.02455512 -0.01587302"
        rpy="0 0 0" />
      <mass
        value="1.438" />
      <inertia
        ixx="0.005898763698368265"
        ixy="0.00016227005634452817"
        ixz="-0.0002683677646477841"
        iyy="0.004384607074686736"
        iyz="0.0012222261915361358"
        izz="0.002612757150912326" />
    </inertial>
    <visual>
      <origin
        xyz="0 0 0"
        rpy="0 0 0" />
      <geometry>
        <mesh
          filename="../meshes/fl_hip_link.stl" />
      </geometry>
      <material
        name="">
        <color
          rgba="1 1 1 1" />
      </material>
    </visual>
    <collision>
      <origin
        xyz="-0.015	0.08	-0.13"
        rpy="0 0 0" />
      <geometry>
      <box size="0.046 0.03 0.18"/>
      </geometry>
    </collision>
  </link>
  <joint
    name="FL_HIP_JOINT"
    type="revolute">
    <origin
      xyz="0.04855 0.01325 0"
      rpy="0 0 0" />
    <parent
      link="FL_ABAD_LINK" />
    <child
      link="FL_HIP_LINK" />
    <axis
      xyz="0 1 0" />
    <limit
      lower="-1.1775"
      upper="2.7475"
      effort="30"
      velocity="20" />
  </joint>
  <link
    name="FL_KNEE_LINK">
    <inertial>
      <origin
        xyz="0.00798892884615243 5.44138171354458e-07 -0.0869849769197685"
        rpy="0 0 0" />
      <mass
        value="0.167" />
      <inertia
        ixx="0.0011816389111495534"
        ixy="5.005448814362472e-10"
        ixz="9.879008924893285e-05"
        iyy="0.0012041157307957258"
        iyz="-8.873206143812424e-09"
        izz="3.4534568769411104e-05" />
    </inertial>
    <visual>
      <origin
        xyz="0 0 0"
        rpy="0 0 0" />
      <geometry>
        <mesh
          filename="../meshes/fl_knee_link.stl" />
      </geometry>
      <material
        name="">
        <color
          rgba="1 1 1 1" />
      </material>
    </visual>
    <collision>
      <origin
        xyz="0.009917	0.0	-0.079793"
        rpy="0	-0.157079633	0" />
      <geometry>
      <box size="0.02 0.02 0.124"/>
      </geometry>
    </collision>
    <collision>
      <origin
        xyz="0.018955	0.0 	-0.18187"
        rpy="0	0.0499164	0" />
      <geometry>
      <box size="0.022 0.022 0.075"/>
      </geometry>
    </collision>
  </link>
  <joint
    name="FL_KNEE_JOINT"
    type="revolute">
    <origin
      xyz="0 0.077399 -0.21"
      rpy="0 0 0" />
    <parent
      link="FL_HIP_LINK" />
    <child
      link="FL_KNEE_LINK" />
    <axis
      xyz="0 1 0" />
    <limit
      lower="-2.7562"
      upper="-0.6978"
      effort="30"
      velocity="20" />
  </joint>
  <link
    name="FL_FOOT_LINK">
    <inertial>
      <origin
        xyz="-2.02372318569566e-07 1.92661398834559e-07 -2.15647114332196e-07"
        rpy="0 0 0" />
      <mass
        value="0.07" />
      <inertia
        ixx="1.4814257783490476e-05"
        ixy="-2.7292533232442304e-15"
        ixz="4.707719327759161e-19"
        iyy="1.481427756599195e-05"
        iyz="-2.908281160870822e-15"
        izz="1.4814257783490594e-05" />
    </inertial>
    <visual>
      <origin
        xyz="0 0 0"
        rpy="0 0 0" />
      <geometry>
        <mesh
          filename="../meshes/fl_foot_link.stl" />
      </geometry>
      <material
        name="">
        <color
          rgba="0.592156862745098 0.666666666666667 0.682352941176471 1" />
      </material>
    </visual>
    <collision>
      <origin
        xyz="0 0 0"
        rpy="0 0 0" />
      <geometry>
      <sphere radius="0.023"/>
      </geometry>
    </collision>
  </link>
  <joint
    name="FL_FOOT_JOINT"
    type="fixed"
    dont_collapse="true">
    <origin
      xyz="0 0 -0.229"
      rpy="0 0 0" />
    <parent
      link="FL_KNEE_LINK" />
    <child
      link="FL_FOOT_LINK" />
    <axis
      xyz="0 0 0" />
  </joint>
  <link
    name="FR_ABAD_LINK">
    <inertial>
      <origin
        xyz="0.0224124762038457 0.0113595096494994 -4.17309715394776e-07"
        rpy="0 0 0" />
      <mass
        value="0.12100290502215937" />
      <inertia
        ixx="8.881476727021421e-05"
        ixy="-3.6101171197753265e-07"
        ixz="2.3010777954627241e-10"
        iyy="0.00011790572554154429"
        iyz="-3.580308709955179e-10"
        izz="0.00010944500944618921" />
    </inertial>
    <visual>
      <origin
        xyz="0 0 0"
        rpy="0 0 0" />
      <geometry>
        <mesh
          filename="../meshes/fr_abad_link.stl" />
      </geometry>
      <material
        name="">
        <color
          rgba="1 1 1 1" />
      </material>
    </visual>
    <collision>
      <origin
        xyz="0.05 -0.08 0"
        rpy="0.0000 -1.5708 1.5708" />
      <geometry>
      <cylinder radius="0.04" length="0.055"/>
      </geometry>
    </collision>
  </link>
  <joint
    name="FR_ABAD_JOINT"
    type="revolute">
    <origin
      xyz="0.144 -0.064181 -2.0143E-05"
      rpy="0 0 0" />
    <parent
      link="BASE_LINK" />
    <child
      link="FR_ABAD_LINK" />
    <axis
      xyz="1 0 0" />
    <limit
      lower="-0.5233"
      upper="0.5233"
      effort="30"
      velocity="20" />
  </joint>
  <link
    name="FR_HIP_LINK">
    <inertial>
      <origin
        xyz="-0.00194205 -0.02455512 -0.01587302"
        rpy="0 0 0" />
      <mass
        value="1.438" />
      <inertia
        ixx="0.005898763698368265"
        ixy="-0.00016227005634452817"
        ixz="-0.0002683677646477841"
        iyy="0.004384607074686736"
        iyz="-0.0012222261915361358"
        izz="0.002612757150912326" />
    </inertial>
    <visual>
      <origin
        xyz="0 0 0"
        rpy="0 0 0" />
      <geometry>
        <mesh
          filename="../meshes/fr_hip_link.stl" />
      </geometry>
      <material
        name="">
        <color
          rgba="1 1 1 1" />
      </material>
    </visual>
    <collision>
      <origin
        xyz="-0.015	-0.08	-0.13"
        rpy="0 0 0" />
      <geometry>
      <box size="0.046 0.03 0.18"/>
      </geometry>
    </collision>
  </link>
  <joint
    name="FR_HIP_JOINT"
    type="revolute">
    <origin
      xyz="0.04855 -0.01325 0"
      rpy="0 0 0" />
    <parent
      link="FR_ABAD_LINK" />
    <child
      link="FR_HIP_LINK" />
    <axis
      xyz="0 1 0" />
    <limit
      lower="-1.1775"
      upper="2.7475"
      effort="30"
      velocity="20" />
  </joint>
  <link
    name="FR_KNEE_LINK">
    <inertial>
      <origin
        xyz="0.00798935286039343 -5.56292452311147e-08 -0.0869799505392584"
        rpy="0 0 0" />
      <mass
        value="0.1670130542472294" />
      <inertia
        ixx="0.0011817208724927378"
        ixy="-9.296587102144549e-10"
        ixz="9.879082784172323e-05"
        iyy="0.0012041985098353398"
        iyz="3.558033744352091e-09"
        izz="3.453588345229152e-05" />
    </inertial>
    <visual>
      <origin
        xyz="0 0 0"
        rpy="0 0 0" />
      <geometry>
        <mesh
          filename="../meshes/fr_knee_link.stl" />
      </geometry>
      <material
        name="">
        <color
          rgba="1 1 1 1" />
      </material>
    </visual>
    <collision>
      <origin
        xyz="0.009917	0.0	-0.079793"
        rpy="0	-0.157079633	0" />
      <geometry>
      <box size="0.02 0.02 0.124"/>
      </geometry>
    </collision>
    <collision>
      <origin
        xyz="0.018955	0.0 	-0.18187"
        rpy="0	0.0499164	0" />
      <geometry>
      <box size="0.022 0.022 0.075"/>
      </geometry>
    </collision>
  </link>
  <joint
    name="FR_KNEE_JOINT"
    type="revolute">
    <origin
      xyz="0 -0.077399 -0.21"
      rpy="0 0 0" />
    <parent
      link="FR_HIP_LINK" />
    <child
      link="FR_KNEE_LINK" />
    <axis
      xyz="0 1 0" />
    <limit
      lower="-2.7562"
      upper="-0.6978"
      effort="30"
      velocity="20" />
  </joint>
  <link
    name="FR_FOOT_LINK">
    <inertial>
      <origin
        xyz="-2.02372318569566e-07 -1.92661398876193e-07 -2.15647114332196e-07"
        rpy="0 0 0" />
      <mass
        value="0.07" />
      <inertia
        ixx="1.4814257783490476e-05"
        ixy="2.7292533791981506e-15"
        ixz="4.707719327759838e-19"
        iyy="1.481427756599195e-05"
        iyz="2.9082812299702925e-15"
        izz="1.4814257783490594e-05" />
    </inertial>
    <visual>
      <origin
        xyz="0 0 0"
        rpy="0 0 0" />
      <geometry>
        <mesh
          filename="../meshes/fr_foot_link.stl" />
      </geometry>
      <material
        name="">
        <color
          rgba="0.592156862745098 0.666666666666667 0.682352941176471 1" />
      </material>
    </visual>
    <collision>
      <origin
        xyz="0.0 0.0 0.0"
        rpy="0 0 0" />
      <geometry>
      <sphere radius="0.023"/>
      </geometry>
    </collision>
  </link>
  <joint
    name="FR_FOOT_JOINT"
    type="fixed"
    dont_collapse="true">
    <origin
      xyz="0 0 -0.229"
      rpy="0 0 0" />
    <parent
      link="FR_KNEE_LINK" />
    <child
      link="FR_FOOT_LINK" />
    <axis
      xyz="0 0 0" />
  </joint>
  <link
    name="RL_ABAD_LINK">
    <inertial>
      <origin
        xyz="-0.022412487802895 -0.011359512648622 4.02582695516185e-06"
        rpy="0 0 0" />
      <mass
        value="0.12100296460958171" />
      <inertia
        ixx="8.881494543825417e-05"
        ixy="-3.6101744655025445e-07"
        ixz="3.839669202629199e-09"
        iyy="0.00011790582316074603"
        iyz="3.513563933486736e-10"
        izz="0.00010944500179177356" />
    </inertial>
    <visual>
      <origin
        xyz="0 0 0"
        rpy="0 0 0" />
      <geometry>
        <mesh
          filename="../meshes/rl_abad_link.stl" />
      </geometry>
      <material
        name="">
        <color
          rgba="1 1 1 1" />
      </material>
    </visual>
    <collision>
      <origin
        xyz="-0.05 0.08 0"
        rpy="0.0000 -1.5708 1.5708" />
      <geometry>
      <cylinder radius="0.04" length="0.055"/>
      </geometry>
    </collision>
  </link>
  <joint
    name="RL_ABAD_JOINT"
    type="revolute">
    <origin
      xyz="-0.144 0.064225 0"
      rpy="0 0 0" />
    <parent
      link="BASE_LINK" />
    <child
      link="RL_ABAD_LINK" />
    <axis
      xyz="1 0 0" />
    <limit
      lower="-0.5233"
      upper="0.5233"
      effort="30"
      velocity="20" />
  </joint>
  <link
    name="RL_HIP_LINK">
    <inertial>
      <origin
        xyz="-0.00194205 0.02455512 -0.01587302"
        rpy="0 0 0" />
      <mass
        value="1.438" />
      <inertia
        ixx="0.005898763698368265"
        ixy="0.00016227005634452817"
        ixz="-0.0002683677646477841"
        iyy="0.004384607074686736"
        iyz="0.0012222261915361358"
        izz="0.002612757150912326" />
    </inertial>
    <visual>
      <origin
        xyz="0 0 0"
        rpy="0 0 0" />
      <geometry>
        <mesh
          filename="../meshes/rl_hip_link.stl" />
      </geometry>
      <material
        name="">
        <color
          rgba="1 1 1 1" />
      </material>
    </visual>
    <collision>
      <origin
        xyz="-0.015	0.08	-0.13"
        rpy="0 0 0" />
      <geometry>
      <box size="0.046 0.03 0.18"/>
      </geometry>
    </collision>
  </link>
  <joint
    name="RL_HIP_JOINT"
    type="revolute">
    <origin
      xyz="-0.04855 0.01325 0"
      rpy="0 0 0" />
    <parent
      link="RL_ABAD_LINK" />
    <child
      link="RL_HIP_LINK" />
    <axis
      xyz="0 1 0" />
    <limit
      lower="-1.1775"
      upper="2.7475"
      effort="30"
      velocity="20" />
  </joint>
  <link
    name="RL_KNEE_LINK">
    <inertial>
      <origin
        xyz="0.00798892953835353 5.44350461428866e-07 -0.0869849698117145"
        rpy="0 0 0" />
      <mass
        value="0.16700002369296388" />
      <inertia
        ixx="0.0011816389762280837"
        ixy="5.003837959403801e-10"
        ixz="9.879008068577583e-05"
        iyy="0.0012041157959467197"
        iyz="-8.874570763997811e-09"
        izz="3.453456951795415e-05" />
    </inertial>
    <visual>
      <origin
        xyz="0 0 0"
        rpy="0 0 0" />
      <geometry>
        <mesh
          filename="../meshes/rl_knee_link.stl" />
      </geometry>
      <material
        name="">
        <color
          rgba="1 1 1 1" />
      </material>
    </visual>
    <collision>
      <origin
        xyz="0.009917	0.0	-0.079793"
        rpy="0	-0.157079633	0" />
      <geometry>
      <box size="0.02 0.02 0.124"/>
      </geometry>
    </collision>
    <collision>
      <origin
        xyz="0.018955	0.0 	-0.18187"
        rpy="0	0.0499164	0" />
      <geometry>
      <box size="0.022 0.022 0.075"/>
      </geometry>
    </collision>
  </link>
  <joint
    name="RL_KNEE_JOINT"
    type="revolute">
    <origin
      xyz="0 0.077399 -0.21"
      rpy="0 0 0" />
    <parent
      link="RL_HIP_LINK" />
    <child
      link="RL_KNEE_LINK" />
    <axis
      xyz="0 1 0" />
    <limit
      lower="-2.7562"
      upper="-0.6978"
      effort="30"
      velocity="20" />
  </joint>
  <link
    name="RL_FOOT_LINK">
    <inertial>
      <origin
        xyz="-2.02372318444666e-07 1.92661398834559e-07 -2.15647113332995e-07"
        rpy="0 0 0" />
      <mass
        value="0.07" />
      <inertia
        ixx="1.4814257783490594e-05"
        ixy="-2.7292533777960923e-15"
        ixz="4.714409840928172e-19"
        iyy="1.481427756599207e-05"
        iyz="-2.9082812164928757e-15"
        izz="1.4814257783490594e-05" />
    </inertial>
    <visual>
      <origin
        xyz="0 0 0"
        rpy="0 0 0" />
      <geometry>
        <mesh
          filename="../meshes/rl_foot_link.stl" />
      </geometry>
      <material
        name="">
        <color
          rgba="0.592156862745098 0.666666666666667 0.682352941176471 1" />
      </material>
    </visual>
    <collision>
      <origin
        xyz="0 0 0"
        rpy="0 0 0" />
      <geometry>
      <sphere radius="0.023"/>
      </geometry>
    </collision>
  </link>
  <joint
    name="RL_FOOT_JOINT"
    type="fixed"
    dont_collapse="true">
    <origin
      xyz="0 0 -0.229"
      rpy="0 0 0" />
    <parent
      link="RL_KNEE_LINK" />
    <child
      link="RL_FOOT_LINK" />
    <axis
      xyz="0 0 0" />
  </joint>
  <link
    name="RR_ABAD_LINK">
    <inertial>
      <origin
        xyz="-0.0224121580976738 0.0113603235206001 3.73366881317727e-06"
        rpy="0 0 0" />
      <mass
        value="0.12100045029579216" />
      <inertia
        ixx="8.880948075555233e-05"
        ixy="3.6065856001657757e-07"
        ixz="2.0654498823476937e-09"
        iyy="0.00011790033688695825"
        iyz="-1.6759670983957215e-09"
        izz="0.00010944136961550325" />
    </inertial>
    <visual>
      <origin
        xyz="0 0 0"
        rpy="0 0 0" />
      <geometry>
        <mesh
          filename="../meshes/rr_abad_link.stl" />
      </geometry>
      <material
        name="">
        <color
          rgba="1 1 1 1" />
      </material>
    </visual>
    <collision>
      <origin
        xyz="-0.05 -0.08 0"
        rpy="0.0000 -1.5708 1.5708" />
      <geometry>
      <cylinder radius="0.04" length="0.055"/>
      </geometry>
    </collision>
  </link>
  <joint
    name="RR_ABAD_JOINT"
    type="revolute">
    <origin
      xyz="-0.144 -0.064181 0"
      rpy="0 0 0" />
    <parent
      link="BASE_LINK" />
    <child
      link="RR_ABAD_LINK" />
    <axis
      xyz="1 0 0" />
    <limit
      lower="-0.5233"
      upper="0.5233"
      effort="30"
      velocity="20" />
  </joint>
  <link
    name="RR_HIP_LINK">
    <inertial>
      <origin
        xyz="-0.00194205 -0.02455512 -0.01587302"
        rpy="0 0 0" />
      <mass
        value="1.438" />
      <inertia
        ixx="0.005898763698368265"
        ixy="-0.00016227005634452817"
        ixz="-0.0002683677646477841"
        iyy="0.004384607074686736"
        iyz="-0.0012222261915361358"
        izz="0.002612757150912326" />
    </inertial>
    <visual>
      <origin
        xyz="0 0 0"
        rpy="0 0 0" />
      <geometry>
        <mesh
          filename="../meshes/rr_hip_link.stl" />
      </geometry>
      <material
        name="">
        <color
          rgba="1 1 1 1" />
      </material>
    </visual>
    <collision>
      <origin
        xyz="-0.015	-0.08	-0.13"
        rpy="0 0 0" />
      <geometry>
      <box size="0.046 0.03 0.18"/>
      </geometry>
    </collision>
  </link>
  <joint
    name="RR_HIP_JOINT"
    type="revolute">
    <origin
      xyz="-0.04855 -0.01325 0"
      rpy="0 0 0" />
    <parent
      link="RR_ABAD_LINK" />
    <child
      link="RR_HIP_LINK" />
    <axis
      xyz="0 1 0" />
    <limit
      lower="-1.1775"
      upper="2.7475"
      effort="30"
      velocity="20" />
  </joint>
  <link
    name="RR_KNEE_LINK">
    <inertial>
      <origin
        xyz="0.00798915209065952 -1.36080421812845e-07 -0.0869792912108696"
        rpy="0 0 0" />
      <mass
        value="0.16701135121073604" />
      <inertia
        ixx="0.001181713334489406"
        ixy="-6.459704524764183e-10"
        ixz="9.878853503991023e-05"
        iyy="0.0012041903722622939"
        iyz="2.6425021982517565e-09"
        izz="3.453505777443375e-05" />
    </inertial>
    <visual>
      <origin
        xyz="0 0 0"
        rpy="0 0 0" />
      <geometry>
        <mesh
          filename="../meshes/rr_knee_link.stl" />
      </geometry>
      <material
        name="">
        <color
          rgba="1 1 1 1" />
      </material>
    </visual>
    <collision>
      <origin
        xyz="0.009917	0.0	-0.079793"
        rpy="0	-0.157079633	0" />
      <geometry>
      <box size="0.02 0.02 0.124"/>
      </geometry>
    </collision>
    <collision>
      <origin
        xyz="0.018955	0.0 	-0.18187"
        rpy="0	0.0499164	0" />
      <geometry>
      <box size="0.022 0.022 0.075"/>
      </geometry>
    </collision>
  </link>
  <joint
    name="RR_KNEE_JOINT"
    type="revolute">
    <origin
      xyz="0 -0.077399 -0.21"
      rpy="0 0 0" />
    <parent
      link="RR_HIP_LINK" />
    <child
      link="RR_KNEE_LINK" />
    <axis
      xyz="0 1 0" />
    <limit
      lower="-2.7562"
      upper="-0.6978"
      effort="30"
      velocity="20" />
  </joint>
  <link
    name="RR_FOOT_LINK">
    <inertial>
      <origin
        xyz="-2.02372318389155e-07 -1.92661398876193e-07 -2.15647113332995e-07"
        rpy="0 0 0" />
      <mass
        value="0.07" />
      <inertia
        ixx="1.4814257783490594e-05"
        ixy="2.729253153971091e-15"
        ixz="4.714409840927044e-19"
        iyy="1.481427756599207e-05"
        iyz="2.9082809400935674e-15"
        izz="1.4814257783490594e-05" />
    </inertial>
    <visual>
      <origin
        xyz="0 0 0"
        rpy="0 0 0" />
      <geometry>
        <mesh
          filename="../meshes/rr_foot_link.stl" />
      </geometry>
      <material
        name="">
        <color
          rgba="0.592156862745098 0.666666666666667 0.682352941176471 1" />
      </material>
    </visual>
    <collision>
      <origin
        xyz="0 0 0"
        rpy="0 0 0" />
      <geometry>
      <sphere radius="0.023"/>
      </geometry>
    </collision>
  </link>
  <joint
    name="RR_FOOT_JOINT"
    type="fixed"
    dont_collapse="true">
    <origin
      xyz="0 0 -0.229"
      rpy="0 0 0" />
    <parent
      link="RR_KNEE_LINK" />
    <child
      link="RR_FOOT_LINK" />
    <axis
      xyz="0 0 0" />
  </joint>
</robot>
