<mujoco model="uni_0417">
<!-- zsirob 250825 -->
  <compiler angle="radian" meshdir="./" autolimits="true"/>

  <option iterations="20" ls_iterations="5" timestep="0.002" integrator="Euler">
    <flag eulerdamp="disable"/>
  </option>


  <default>
    <default class="go1">

      <geom condim="1" contype="0" conaffinity="1"/>
      <joint axis="0 1 0" armature="0.01" damping="0.05"/>
      <position forcerange="-30 30" inheritrange="1.5" kp="50"/>

      <default class="abduction">
        <joint axis="1 0 0" range="-0.5233 0.5233" frictionloss="0.3"  margin="0.02" solreflimit="0.001 1"/>
        <!-- <joint axis="1 0 0" range="-0.863 0.863" frictionloss="0.3"  margin="0.02" solreflimit="0.001 1"/> -->
      </default>

      <default class="hip">
        <joint range="-1.1775 2.7475" frictionloss="0.3"  margin="0.02" solreflimit="0.001 1"/>
      </default>
      
      <default class="knee">
        <!-- <joint range="-2.723 -0.602" frictionloss="1.0"/> -->
        <joint range="-2.7562 -0.6978" frictionloss="0.3" margin="0.02" solreflimit="0.001 1"/>
      </default>

      <default class="visual">
        <geom type="mesh" contype="0" conaffinity="0" group="2" material="dark"/>
      </default>

      <default class="collision">
        <geom group="3" type="capsule"/>
        <default class="foot">
          <geom type="sphere" size="0.023" pos="0 0 0" solimp="0.9 .95 0.023" condim="3"/>
          <!-- <geom type="sphere" size="0.023" pos="0 0 -0.213" solimp="0.9 .95 0.001" condim="3"/> -->
        </default>
      </default>

    </default>
  </default>

  <asset>
    <material name="dark" rgba="0.2 0.2 0.2 1"/>
    <material name="none" rgba="0.75294 0.75294 0.75294 1" />
    <material name="default_material" rgba="0.7 0.7 0.7 1" />
    <material name="collision_material" rgba="1.0 0.28 0.1 0.9" />
    <mesh name="BASE_LINK.STL" file="BASE_LINK.STL" />
    <mesh name="FL_ABAD_LINK.STL" file="FL_ABAD_LINK.STL" />
    <mesh name="FL_HIP_LINK.STL" file="FL_HIP_LINK.STL" />
    <mesh name="FL_KNEE_LINK.STL" file="FL_KNEE_LINK.STL" />
    <mesh name="FL_FOOT_LINK.STL" file="FL_FOOT_LINK.STL" />
    <mesh name="FR_ABAD_LINK.STL" file="FR_ABAD_LINK.STL" />
    <mesh name="FR_HIP_LINK.STL" file="FR_HIP_LINK.STL" />
    <mesh name="FR_KNEE_LINK.STL" file="FR_KNEE_LINK.STL" />
    <mesh name="FR_FOOT_LINK.STL" file="FR_FOOT_LINK.STL" />
    <mesh name="RR_ABAD_LINK.STL" file="RR_ABAD_LINK.STL" />
    <mesh name="RR_HIP_LINK.STL" file="RR_HIP_LINK.STL" />
    <mesh name="RR_KNEE_LINK.STL" file="RR_KNEE_LINK.STL" />
    <mesh name="RR_FOOT_LINK.STL" file="RR_FOOT_LINK.STL" />
    <mesh name="RL_ABAD_LINK.STL" file="RL_ABAD_LINK.STL" />
    <mesh name="RL_HIP_LINK.STL" file="RL_HIP_LINK.STL" />
    <mesh name="RL_KNEE_LINK.STL" file="RL_KNEE_LINK.STL" />
    <mesh name="RL_FOOT_LINK.STL" file="RL_FOOT_LINK.STL" />
  </asset>

  <worldbody>
    <!-- <geom name="floor" type="plane"
        pos="0 0 0"
        size="10 10 0.05"
        contype="1" conaffinity="1"
        rgba="0.9 0.9 0.9 1"/> -->
    <light name="spotlight" mode="targetbodycom" target="BASE_LINK" pos="3 0 4"/>
    <body name="BASE_LINK"  pos="0 0 0.4" childclass="go1" quat="1 0 0 0">
      <camera name="track" pos="0.846 -1.3 0.316" xyaxes="0.866 0.500 0.000 -0.171 0.296 0.940" mode="trackcom"/>
      <camera name="top" pos="-1 0 1" xyaxes="0 -1 0 0.7 0 0.7" mode="trackcom"/>
      <camera name="side" pos="0 -1 .3" xyaxes="1 0 0 0 1 2" mode="trackcom"/>
      <camera name="back" pos="-1 0 .3" xyaxes="0 -1 0 1 0 2" mode="trackcom"/>
      <inertial pos="0.014501881818807 -0.000289250801671 0.013238465807008" quat="-0.0076083635337945155 0.6942254418113303 -0.00728014172674013 0.7196805876794534" mass="7.30032053935248" diaginertia="0.1026006987158561 0.08404328046371345 0.03227102139098372"/>

      <freejoint/>
      
      <geom class="visual" type="mesh" rgba="0.592156862745098 0.666666666666667 0.682352941176471 1" mesh="BASE_LINK.STL" />
      <geom name="case" class="collision" type="box" size="0.245 0.1095 0.06" pos="-0.005 0 0.011469"/>
      <geom name="case_1" class="collision" type="box" size="0.0125 0.0166 0.045" pos="0.25239 0 -0.00332" quat="0.993571856 0 0.113203214 0"/>
      <geom name="case_2" class="collision" type="box" size="0.055 0.053 0.036" pos="0.23335 0 0.076435"/>
      <!-- <geom name="NX" class="collision" type="box" size="0.05 0.06 0.02" pos="-0.03 0 0.09"/> -->

      <site name="case" pos="0 0 0" rgba="1 0 0 1" size="0.02" group="5"/>
      <site name="imu" pos="0 0 0" rgba="0 1 0 1" size="0.02" group="5"/>
      <body name="PAYLOAD_LINK" pos="0 0 0.075725056">
        <inertial pos="0 0 0" mass="0.01" diaginertia="0.00002 0.00003 0.00004"/>
        <geom
          name="payload_geom"
          type="box"
          size="0.09345 0.066 0.005"
          pos="0 0 0"
          contype="0"
          conaffinity="0"
          density="0"
          rgba="0.8 0.2 0.2 0.3"
        />
      </body>

      <body name="FL_ABAD_LINK" pos="0.144 0.064225 -2.0143e-05">
        <inertial pos="0.0144424564697362 -0.00600368145551691 -1.87988493965952e-07" quat="0.5291736825142328 0.5292105089455847 0.46897609668839413 0.46901265621601496" mass="0.320329944374416" diaginertia="0.00047783943255139626 0.00046908698480158334 0.0001241081155081985"/>

        <joint class="abduction" name="FL_ABAD_JOINT" pos="0 0 0" axis="1 0 0"/>
        <geom type="mesh" class="visual" rgba="1 1 1 1" mesh="FL_ABAD_LINK.STL"/>
        <!-- FL_ABAD_Collision --> 
        <geom name="FL_ABAD_COL" class="collision" type="cylinder" size="0.04 0.0275" pos="0.05 0.08 0" quat="0.499998163 0.500001837 -0.5 0.5"/>
        
        <body name="FL_HIP_LINK" pos="0.04855 0.01325 0">
          <inertial pos="-0.00048600000000000016 0.03225 -0.02093473684210526" quat="0.9731445081294574 0.22538963062352477 0.04541992243914374 -0.011238832256468578" mass="1.33" diaginertia="0.005615092772179515 0.0049505271280553395 0.0015907903549875844"/>
          <joint class="hip" name="FL_HIP_JOINT" pos="0 0 0" axis="0 1 0" />
          <!-- <site name="FL_ABAD_LINK" pos="0 0.085 0" type="sphere" size="0.02" rgba="0 1 0 1" group="5"/> -->
          <site name="FL_hip" pos="0 0.0 0" type="sphere" size="0.02" rgba="0 1 0 1" group="5"/>

          <geom type="mesh" class="visual" rgba="1 1 1 1" mesh="FL_HIP_LINK.STL" />
          <!-- FL_HIP_Collision --> 
          <geom name="FL_HIP_COL" class="collision" type="box" size="0.023 0.015 0.09" pos="-0.015 0.08 -0.13" quat="1 0 0 0"/>

          <body name="FL_KNEE_LINK" pos="0 0.077399 -0.21">
            <inertial pos="0.00798892884543451 5.44137953750745e-07 -0.0869849769173929" quat="0.7064576324739475 -0.03014641061466151 -0.03014053077085178 0.7064703502987295" mass="0.14" diaginertia="0.0010094383372615727 0.0009976757599102577 2.1870869909055355e-05"/>
            <!-- <site name="FL_knee" pos="0 0.015 0" type="sphere" size="0.02" rgba="0 1 0 1" group="5"/> -->
            <site name="FL_knee" pos="0 0.0 0" type="sphere" size="0.02" rgba="0 1 0 1" group="5"/>

            <joint class="knee" name="FL_KNEE_JOINT" pos="0 0 0" axis="0 1 0" />

                    <geom type="mesh" class="visual" rgba="1 1 1 1" mesh="FL_KNEE_LINK.STL" />
                    <!-- FL_KNEE_Collision --> 
                    <geom name="FL_KNEE_COL_0" class="collision" type="box" size="0.01 0.01 0.062" pos="0.009917 0 -0.079793" quat="0.996917334 0 -0.0784590959 0"/>
                    <geom name="FL_KNEE_COL_1" class="collision" type="box" size="0.011 0.011 0.0375" pos="0.018955 0 -0.18187" quat="0.99968856 0 0.024955609 0"/>

                    <body name="FL_FOOT_LINK" pos="0 0 -0.229">
                    <geom pos="0 0 0" type="mesh" class="visual" rgba="0.592156862745098 0.666666666666667 0.682352941176471 1" mesh="FL_FOOT_LINK.STL" />
                    <inertial pos="-2.02372318569566e-07 1.92661398834559e-07 -2.15647114332196e-07" quat="0.707106781186548 0 0 0.707106781186548" mass="0.0589523342854384" diaginertia="1.24762320466804e-05 1.24762153863284e-05 1.24762153863285e-05" />
                    <!-- FL_FOOT_Collision --> 
                    <geom name="FL" class="foot" pos="0 0 0"/>
                    <site name="FL" pos="0 0 0" type="sphere" size="0.023" quat="0 0 1 1" group="5"/>
                    </body>


          </body>
        </body>
      </body>


      <body name="FR_ABAD_LINK" pos="0.144 -0.064181 -2.0143e-05">
        <inertial pos="0.014442558979466 0.00600357212318758 -5.04034752824012e-08" quat="0.4689967342827985 0.4689920459643406 0.529194161742345 0.5291900067386679" mass="0.320332974895231" diaginertia="0.00047784300790091016 0.0004690887949312498 0.00012411096159625467"/>

        <joint class="abduction" name="FR_ABAD_JOINT" pos="0 0 0" axis="1 0 0"/>
        <geom type="mesh" class="visual" rgba="1 1 1 1" mesh="FR_ABAD_LINK.STL"/>
        <!-- FR_ABAD_Collision --> 
        <geom name="FR_ABAD_COL" class="collision" type="cylinder" size="0.04 0.0275" pos="0.05 -0.08 0" quat="0.499998163 0.500001837 -0.5 0.5"/>
        
        <body name="FR_HIP_LINK" pos="0.04855 -0.01325 0">
          <inertial pos="-0.00048600000000000016 -0.03225 -0.02093473684210526" quat="0.9731444294565023 -0.22538978092494474 0.04542027146479661 0.011241219348831186" mass="1.33" diaginertia="0.005615092782114939 0.004950529438277558 0.0015907880348299617"/>
          <joint class="hip" name="FR_HIP_JOINT" pos="0 0 0" axis="0 1 0" />
          <!-- <site name="FR_ABAD_LINK" pos="0 -0.085 0" type="sphere" size="0.02" rgba="0 1 0 1" group="5"/> -->
          <site name="FR_hip" pos="0 -0.0 0" type="sphere" size="0.02" rgba="0 1 0 1" group="5"/>

          <geom type="mesh" class="visual" rgba="1 1 1 1" mesh="FR_HIP_LINK.STL" />
          <!-- FR_HIP_Collision --> 
          <geom name="FR_HIP_COL" class="collision" type="box" size="0.023 0.015 0.09" pos="-0.015 -0.08 -0.13" quat="1 0 0 0"/>

          <body name="FR_KNEE_LINK" pos="0 -0.077399 -0.21">
            <inertial pos="0.00798935285968155 -5.562946018417e-08 -0.0869799505369122" quat="0.7064483359229148 -0.03014119732260282 -0.030142031975394182 0.7064798049513519" mass="0.14" diaginertia="0.001009428826647702 0.0009976660978701006 2.1870647898408354e-05"/>
            <!-- <site name="FR_knee" pos="0 -0.015 0" type="sphere" size="0.02" rgba="0 1 0 1" group="5"/> -->
            <site name="FR_knee" pos="0 -0.0 0" type="sphere" size="0.02" rgba="0 1 0 1" group="5"/>

            <joint class="knee" name="FR_KNEE_JOINT" pos="0 0 0" axis="0 1 0" />
            <geom type="mesh" class="visual" rgba="1 1 1 1" mesh="FR_KNEE_LINK.STL" />
            <!-- FL_KNEE_Collision --> 
            <geom name="FR_KNEE_COL_0" class="collision" type="box" size="0.01 0.01 0.062" pos="0.009917 0 -0.079793" quat="0.996917334 0 -0.0784590959 0"/>
            <geom name="FR_KNEE_COL_1" class="collision" type="box" size="0.011 0.011 0.0375" pos="0.018955 0 -0.18187" quat="0.99968856 0 0.024955609 0"/>
     
            <body name="FR_FOOT_LINK" pos="0 0 -0.229">
            <geom pos="0 0 0" type="mesh" class="visual" rgba="0.592156862745098 0.666666666666667 0.682352941176471 1" mesh="FR_FOOT_LINK.STL" />
            <inertial pos="-2.02372318569566e-07 -1.92661398876193e-07 -2.15647114332196e-07" quat="0.707106781186548 0 0 0.707106781186548" mass="0.0589523342854384" diaginertia="1.24762320466804e-05 1.24762153863284e-05 1.24762153863285e-05" />
            <geom name="FR" class="foot" pos="0 0 0"/>
            <site name="FR"  type="sphere" size="0.023" pos="0 0 0" quat="0 0 1 1" group="5"/>
            </body>


          </body>
        </body>
      </body>
      

      <body name="RL_ABAD_LINK" pos="-0.144 0.064225 0">
        <inertial pos="-0.014442562925683 -0.00600357336453766 2.79936310140783e-06" quat="0.4689405748872544 0.46904819090527616 0.5292365881605203 0.5291475839358177" mass="0.320333006502764" diaginertia="0.00047784310557411253 0.000469088820601089 0.0001241110901784922"/>

        <joint class="abduction" name="RL_ABAD_JOINT" pos="0 0 0" axis="1 0 0"/>
        <geom type="mesh" class="visual" rgba="1 1 1 1" mesh="RL_ABAD_LINK.STL"/>
        <!-- RL_ABAD_Collision --> 
        <geom name="RL_ABAD_COL" class="collision" type="cylinder" size="0.04 0.0275" pos="-0.05 0.08 0" quat="0.499998163 0.500001837 -0.5 0.5"/>
        
        <body name="RL_HIP_LINK" pos="-0.04855 0.01325 0">
          <inertial pos="-0.00048600000000000016 0.03225 -0.02093473684210526" quat="0.9731445081294574 0.22538963062352477 0.04541992243914374 -0.011238832256468578" mass="1.33" diaginertia="0.005615092772179515 0.0049505271280553395 0.0015907903549875844"/>
          <joint class="hip" name="RL_HIP_JOINT" pos="0 0 0" axis="0 1 0" />
          <!-- <site name="RL_ABAD_LINK" pos="0 0.085 0" type="sphere" size="0.02" rgba="0 1 0 1" group="5"/> -->
          <site name="RL_hip" pos="0 0.0 0" type="sphere" size="0.02" rgba="0 1 0 1" group="5"/>

          <geom type="mesh" class="visual" rgba="1 1 1 1" mesh="RL_HIP_LINK.STL" />
          <!-- RL_HIP_Collision --> 
          <geom name="RL_HIP_COL" class="collision" type="box" size="0.023 0.015 0.09" pos="-0.015 0.08 -0.13" quat="1 0 0 0"/>

          <body name="RL_KNEE_LINK" pos="0 0.077399 -0.21">
            <inertial pos="0.00798892953763553 5.44350242936975e-07 -0.08698496980934" quat="0.7064576257064045 -0.03014640709960361 -0.030140525850325388 0.7064703574260721" mass="0.14" diaginertia="0.0010094382486661386 0.0009976756713130038 2.187086904348538e-05"/>
            <!-- <site name="RL_knee" pos="0 0.015 0" type="sphere" size="0.02" rgba="0 1 0 1" group="5"/> -->
            <site name="RL_knee" pos="0 0.0 0" type="sphere" size="0.02" rgba="0 1 0 1" group="5"/>

            <joint class="knee" name="RL_KNEE_JOINT" pos="0 0 0" axis="0 1 0" />
            <geom type="mesh" class="visual" rgba="1 1 1 1" mesh="RL_KNEE_LINK.STL" />
            <!-- RL_KNEE_Collision --> 
            <geom name="RL_KNEE_COL_0" class="collision" type="box" size="0.01 0.01 0.062" pos="0.009917 0 -0.079793" quat="0.996917334 0 -0.0784590959 0"/>
            <geom name="RL_KNEE_COL_1" class="collision" type="box" size="0.011 0.011 0.0375" pos="0.018955 0 -0.18187" quat="0.99968856 0 0.024955609 0"/>
     
            <body name="RL_FOOT_LINK" pos="0 0 -0.229">
            <geom pos="0 0 0" type="mesh" class="visual" rgba="0.592156862745098 0.666666666666667 0.682352941176471 1" mesh="RL_FOOT_LINK.STL" />
            <inertial pos="-2.02372318444666e-07 1.92661398834559e-07 -2.15647113332995e-07" quat="0.707106781186548 0 0 0.707106781186548" mass="0.0589523342854384" diaginertia="1.24762320466805e-05 1.24762153863285e-05 1.24762153863285e-05" />
            <geom name="RL" class="foot" pos="0 0 0"/>
            <site name="RL" type="sphere" size="0.023" pos="0 0 0" group="5"/>
            </body>


          </body>
        </body>
      </body>
      

      <body name="RR_ABAD_LINK" pos="-0.144 -0.064181 0">
        <inertial pos="-0.0144424500070948 0.00600367002172289 2.64158132828873e-06" quat="0.5291656722469249 0.5292185501466036 0.46906623712092627 0.4689224698064746" mass="0.320330247102786" diaginertia="0.00047783956217325904 0.0004690870634743024 0.00012410820705626772"/>

        <joint class="abduction" name="RR_ABAD_JOINT" pos="0 0 0" axis="1 0 0"/>
        <geom type="mesh" class="visual" rgba="1 1 1 1" mesh="RR_ABAD_LINK.STL"/>
        <!-- RR_ABAD_Collision --> 
        <geom name="RR_ABAD_COL" class="collision" type="cylinder" size="0.04 0.0275" pos="-0.05 -0.08 0" quat="0.499998163 0.500001837 -0.5 0.5"/>
        
        <body name="RR_HIP_LINK" pos="-0.04855 -0.01325 0">
          <inertial pos="-0.00048600000000000016 -0.03225 -0.02093473684210526" quat="0.9731444294565023 -0.22538978092494474 0.04542027146479661 0.011241219348831186" mass="1.33" diaginertia="0.005615092782114939 0.004950529438277558 0.0015907880348299617"/>
          <joint class="hip" name="RR_HIP_JOINT" pos="0 0 0" axis="0 1 0" />
          <!-- <site name="RR_ABAD_LINK" pos="0 -0.085 0" type="sphere" size="0.02" rgba="0 1 0 1" group="5"/> -->
          <site name="RR_hip" pos="0 -0.0 0" type="sphere" size="0.02" rgba="0 1 0 1" group="5"/>

          <geom type="mesh" class="visual" rgba="1 1 1 1" mesh="RR_HIP_LINK.STL" />
          <!-- RL_HIP_Collision --> 
          <geom name="RR_HIP_COL" class="collision" type="box" size="0.023 0.015 0.09" pos="-0.015 -0.08 -0.13" quat="1 0 0 0"/>

          <body name="RR_KNEE_LINK" pos="0 -0.077399 -0.21">
            <inertial pos="0.00798915208994713 -1.36080637355707e-07 -0.0869792912085275" quat="0.7064535218318484 -0.030140745448694866 -0.030141458256116766 0.7064746629917955" mass="0.14" diaginertia="0.0010094322984541605 0.0009976696669602042 2.187046418156173e-05"/>
            <!-- <site name="RR_knee" pos="0 -0.015 0" type="sphere" size="0.02" rgba="0 1 0 1" group="5"/> -->
            <site name="RR_knee" pos="0 -0.0 0" type="sphere" size="0.02" rgba="0 1 0 1" group="5"/>

            <joint class="knee" name="RR_KNEE_JOINT" pos="0 0 0" axis="0 1 0" />

                    <geom type="mesh" class="visual" rgba="1 1 1 1" mesh="RR_KNEE_LINK.STL" />
                  <!-- RL_KNEE_Collision --> 
                  <geom name="RR_KNEE_COL_0" class="collision" type="box" size="0.01 0.01 0.062" pos="0.009917 0 -0.079793" quat="0.996917334 0 -0.0784590959 0"/>
                  <geom name="RR_KNEE_COL_1" class="collision" type="box" size="0.011 0.011 0.0375" pos="0.018955 0 -0.18187" quat="0.99968856 0 0.024955609 0"/>
                  <body name="RR_FOOT_LINK" pos="0 0 -0.229">
                  <geom pos="0 0 0" type="mesh" class="visual" rgba="0.592156862745098 0.666666666666667 0.682352941176471 1" mesh="RR_FOOT_LINK.STL" />
                  <inertial pos="-2.02372318389155e-07 -1.92661398876193e-07 -2.15647113332995e-07" quat="0.707106781186548 0 0 0.707106781186548" mass="0.0589523342854384" diaginertia="1.24762320466805e-05 1.24762153863285e-05 1.24762153863285e-05" />
                  <geom name="RR" class="foot" pos="0 0 0"/>
                  <site name="RR" type="sphere" size="0.023" pos="0 0 0" group="5"/>
                  </body>


          </body>
        </body>
      </body>


    </body>
  </worldbody>

  
  <!-- <actuator>
    <motor class="abduction" name="FL_hip" joint="FL_ABAD_JOINT" ctrlrange="-30 30" gear="1" />
    <motor class="hip" name="FL_thigh" joint="FL_HIP_JOINT" ctrlrange="-30 30" gear="1"/>
    <motor class="knee" name="FL_calf" joint="FL_KNEE_JOINT" ctrlrange="-30 30" gear="1"/>
    <motor class="abduction" name="FR_hip" joint="FR_ABAD_JOINT" ctrlrange="-30 30" gear="1"/>
    <motor class="hip" name="FR_thigh" joint="FR_HIP_JOINT" ctrlrange="-30 30" gear="1"/>
    <motor class="knee" name="FR_calf" joint="FR_KNEE_JOINT" ctrlrange="-30 30" gear="1"/>
    <motor class="abduction" name="RL_hip" joint="RL_ABAD_JOINT" ctrlrange="-30 30" gear="1"/>
    <motor class="hip" name="RL_thigh" joint="RL_HIP_JOINT" ctrlrange="-30 30" gear="1"/>
    <motor class="knee" name="RL_calf" joint="RL_KNEE_JOINT" ctrlrange="-30 30" gear="1"/>
    <motor class="abduction" name="RR_hip" joint="RR_ABAD_JOINT" ctrlrange="-30 30" gear="1"/>
    <motor class="hip" name="RR_thigh" joint="RR_HIP_JOINT" ctrlrange="-30 30" gear="1"/>
    <motor class="knee" name="RR_calf" joint="RR_KNEE_JOINT" ctrlrange="-30 30" gear="1"/>
  </actuator> -->

  <actuator>
    <position class="abduction" name="FL_hip" joint="FL_ABAD_JOINT" />
    <position class="hip" name="FL_thigh" joint="FL_HIP_JOINT"/>
    <position class="knee" name="FL_calf" joint="FL_KNEE_JOINT"/>
    <position class="abduction" name="FR_hip" joint="FR_ABAD_JOINT"/>
    <position class="hip" name="FR_thigh" joint="FR_HIP_JOINT"/>
    <position class="knee" name="FR_calf" joint="FR_KNEE_JOINT"/>
    <position class="abduction" name="RL_hip" joint="RL_ABAD_JOINT"/>
    <position class="hip" name="RL_thigh" joint="RL_HIP_JOINT"/>
    <position class="knee" name="RL_calf" joint="RL_KNEE_JOINT"/>
    <position class="abduction" name="RR_hip" joint="RR_ABAD_JOINT"/>
    <position class="hip" name="RR_thigh" joint="RR_HIP_JOINT"/>
    <position class="knee" name="RR_calf" joint="RR_KNEE_JOINT"/>
  </actuator>
  
  <sensor>
    <gyro site="imu" name="gyro"/>
    <velocimeter site="imu" name="local_linvel"/>
    <accelerometer site="imu" name="accelerometer"/>
    <framepos objtype="site" objname="imu" name="position"/>
    <framezaxis objtype="site" objname="imu" name="upvector"/>
    <framexaxis objtype="site" objname="imu" name="forwardvector"/>
    <framelinvel objtype="site" objname="imu" name="global_linvel"/>
    <frameangvel objtype="site" objname="imu" name="global_angvel"/>
    <framequat objtype="site" objname="imu" name="orientation"/>
    <framelinvel objtype="site" objname="FL" name="FL_global_linvel"/>
    <framelinvel objtype="site" objname="FR" name="FR_global_linvel"/>
    <framelinvel objtype="site" objname="RL" name="RL_global_linvel"/>
    <framelinvel objtype="site" objname="RR" name="RR_global_linvel"/>
     <framepos objtype="site" objname="FL" name="FL_pos" reftype="site" refname="imu"/>
    <framepos objtype="site" objname="FR" name="FR_pos" reftype="site" refname="imu"/>
    <framepos objtype="site" objname="RL" name="RL_pos" reftype="site" refname="imu"/>
    <framepos objtype="site" objname="RR" name="RR_pos" reftype="site" refname="imu"/>
    <!-- <framepos objtype="site" objname="head" name="head_pos"/> -->
    <touch site="FL" name="FL_contact_force"/>
    <touch site="FR" name="FR_contact_force"/>
    <touch site="RL" name="RL_contact_force"/>
    <touch site="RR" name="RR_contact_force"/>
  </sensor>
</mujoco>
